Workbook

Sheet 00_Обзор
A1: Стартовая схема проекта ToS/KAG v6.1
A2: Фундаментальные таблицы, governance-слой, traceable generation path и generated serving views
A4: Главный принцип | B4: Сначала маленькое устойчивое ядро таблиц, затем проекции и новые таблицы поверх него.
A5: Текущий режим | B5: Горизонтальная волна: широкое покрытие корпуса. Вертикальная волна: углубление плотных мест.
A6: Базовый пакет | B6: corpus_map, witnesses, segments, nodes, event_state_nodes, edges, translation_tensions
A7: Вторая волна | B7: witness_glosses, principles, predicates_registry, class_registry
A8: Serving-слой | B8: master_view, coverage_view и чистые actual-проекции генерируются из authoring tables
A9: Стоп-правило | B9: Новая таблица нужна только если она делает отдельную работу: provenance, слой утверждения, новый тип вопроса, снижение дублирования или governance.
A11: Таблица | B11: Слой | C11: Когда начинать | D11: Зачем нужна | E11: Начинать сразу? | F11: Когда спавнить дальше
A12: corpus_map | B12: фундаментальный | C12: сразу | D12: карта корпуса и стабильная адресация | E12: да | F12: если нужен адрес книги/главы/части/абзаца
A13: witnesses | B13: фундаментальный | C13: сразу | D13: кто говорит и в каком статусе | E13: да | F13: если есть 2+ witness-слоя или нужен provenance
A14: segments | B14: фундаментальный | C14: сразу | D14: общие локаторы и spine | E14: да | F14: если текст режется на обозримые единицы [n]
A15: nodes | B15: фундаментальный | C15: сразу | D15: устойчивые сущности, символы, понятия | E15: да | F15: если смысл должен переиспользоваться
A16: event_state_nodes | B16: фундаментальный | C16: сразу | D16: события и состояния, где тройка тесна | E16: да | F16: если есть длительность / множественные участники / условность
A17: edges | B17: фундаментальный | C17: сразу | D17: нормализованные связи | E17: да | F17: если есть хотя бы 1 нормализованный узел
A18: translation_tensions | B18: фундаментальный+ | C18: сразу, но скупо | D18: нагрузочные дрейфы между witness-слоями | E18: да | F18: только если дрейф философски значим
A19: witness_glosses | B19: вторая волна | C19: по мере сгущения | D19: лексическая поверхность witness-а | E19: нет | F19: если важно не растворить genoss / вкушал / delighted in
A20: principles | B20: вторая волна | C20: по мере сгущения | D20: снятые принципы и authored commentary | E20: нет | F20: если узел уже читается как principle, а не только факт
A21: analogy_nodes | B21: третья волна | C21: когда накопятся повторяющиеся аналогии | D21: отдельные образные мосты | E21: нет | F21: если аналогии становятся запросопригодными
A22: reasoning_paths | B22: третья волна | C22: когда появляются вопросы почему/как | D22: маршруты рассуждения | E22: нет | F22: если нужен объяснимый путь от вопроса к ответу
... A25: predicates_registry / class_registry | B25: вторая волна+ | C25: после стабилизации первого pilot-а | D25: governance-слой для предикатов и классов | E25: нет | F25: если начинается enum drift и почти-дубли
A27: Правила роста
A28: № | B28: Правило
A29: 1 | B29: Один смысл -> один node_id. Не плодить языковые копии одного и того же узла.
A30: 2 | B30: witness ≠ layer. Witness отвечает за происхождение текста, layer отвечает за режим утверждения.
A31: 3 | B31: Комментарии и принципы не маскируются под source fact.
A32: 4 | B32: Event/state node создается, когда плоская тройка теряет важную структуру.
A33: 5 | B33: Translation tensions фиксируются только там, где дрейф реально меняет философский вес.
A34: 6 | B34: Новая таблица оправдана, если открывает новый тип запроса или снимает путаницу.
A36: Новые листы | B36: 13_Проектная_схема, 14_Порядок_прохода, 20-23 листы контроля и traceable generation path расширяют стартовый пакет до устойчивого проектного каркаса.

Sheet 01_Ключи
A1: Общий словарь ключей и anchor-контракта v6.1
A2: Эти поля склеивают authoring tables, registries и serving views
A4: Ключ | B4: Где живёт | C4: Что означает | D4: Пример | E4: Правило
A5: source_secondary | B5: corpus_map / segments / anchors | C5: человеческий вторичный адрес внутри произведения | D5: 1,1,1,8 | E5: стабилен; не переиспользуется для другого места
A6: sort_key | B6: corpus_map / segments | C6: строгий порядок обхода | D6: 8 | E6: единственный canonical порядок
A7: paragraph_anchor | B7: segments / coverage_view | C7: локальный номер абзаца внутри bounded route | D7: [8] | E7: общий для de / ru / en
A8: segment_id | B8: segments и дальше почти везде | C8: машинно-стабильный идентификатор сегмента | D8: seg.1.1.1.8 | E8: один на общий paragraph-aligned segment
A9: witness_id | B9: witnesses / glosses / tensions | C9: какой текстовый свидетель говорит | D9: w.ru.dionysus.translation.v1 | E9: всегда явный provenance
A10: node_id | B10: nodes / edges / principles | C10: устойчивый смысловой узел | D10: n.underworld | E10: не зависит от языка поверхности
A11: es_id | B11: event_state_nodes / edges | C11: узел события или состояния | D11: ev.p7_8.descent_named_as_go_under | E11: создается, когда тройка тесна
A12: principle_id | B12: principles / edges | C12: узел принципа или claim-а | D12: pr.descent_is_required_by_gift | E12: не маскируется под source fact
A13: edge_id | B13: edges | C13: одна нормализованная связь | D13: e63 | E13: минимальная единица графовой связи
A14: edge_kind | B14: edges / master_view | C14: тип relation row | D14: source_edge | E14: source_edge / bridge_edge / principle_edge
A15: anchor_mode | B15: event_state_nodes / principles / edges | C15: single или multi anchor | D15: multi | E15: один договор range-привязки
... A20: layer | B20: nodes / event_state_nodes / principles / edges | C20: режим утверждения | D20: source_linked / distilled_principle / authored_commentary | E20: не смешивать с witness

Sheet 02_corpus_map
A1: Схема: corpus_map
A2: Адресное дерево корпуса. На этом слое ты можешь пройти хоть всю книгу.
A4: Таблица | B4: corpus_map
A5: Волна | B5: фундаментальный
A6: Назначение | B6: дать каждому текстовому месту стабильный адрес и порядок обхода
A7: Обязательность | B7: заводить сразу
A8: Первичный ключ | B8: corpus_row_id
A9: Зависит от | B9: ни от чего, это корневая карта
A10: Когда спавнить | B10: никогда не заменяется; только расширяется новыми строками
A11: Правило заполнения | B11: одна строка = одно адресуемое место корпуса; не придумывать скрытых уровней
A13: Поля
A14: Поле | B14: Обязат. | C14: Тип | D14: Описание | E14: Пример | F14: Правило
A15: corpus_row_id | B15: да | C15: string | D15: технический id строки карты | E15: cm.1.1.1.8 | F15: стабилен
A16: work_id | B16: да | C16: string | D16: id произведения | E16: thus-spoke-zarathustra | F16: один на книгу/корпус
A17: part_no | B17: да | C17: integer | D17: номер части | E17: 1 | F17: если уровень есть
A18: chapter_no | B18: да | C18: integer | D18: номер главы | E18: 1 | F18: если уровень есть
A19: subchapter_no | B19: да | C19: integer | D19: номер части главы | E19: 1 | F19: для твоего secondary
A20: paragraph_no | B20: да | C20: integer | D20: номер абзаца | E20: 8 | F20: для paragraph spine
A21: source_secondary | B21: да | C21: string | D21: человеческий вторичный адрес | E21: 1,1,1,8 | F21: главный внешний якорь
A22: sort_key | B22: да | C22: integer | D22: порядок обхода | E22: 8 | F22: строгий порядок
A23: title_ru | B23: нет | C23: string | D23: рабочее имя места | E23: untergehen как выбранный спуск | F23: не обязательно
A24: title_en | B24: нет | C24: string | D24: рабочее английское имя места | E24: chosen descent as go-under | F24: если нужен bridge/export
A25: note | B25: нет | C25: text | D25: служебная заметка | E25: абзац пролога | F25: без толкования
A27: Канонический пример строки
A28: corpus_row_id | B28: work_id | C28: part_no | D28: chapter_no | E28: subchapter_no | F28: paragraph_no | G28: source_secondary | H28: sort_key | I28: title_ru | J28: title_en | K28: note
A29: cm.1.1.1.8 | B29: thus-spoke-zarathustra | C29: 1 | D29: 1 | E29: 1 | F29: 8 | G29: 1,1,1,8 | H29: 8 | I29: untergehen как выбранный спуск | J29: chosen descent as go-under | K29: локатор пролога [8]

Sheet 03_witnesses
A1: Схема: witnesses
A2: Кто говорит и в каком статусе.
A4: Таблица | B4: witnesses
A5: Волна | B5: фундаментальный
A6: Назначение | B6: держать provenance явным и не путать canonical source с переводом, bridge или agent layer
A7: Обязательность | B7: заводить сразу
A8: Первичный ключ | B8: witness_id
A9: Зависит от | B9: на corpus_map только логически
A10: Когда спавнить | B10: новая строка на каждый новый witness-слой
A11: Правило заполнения | B11: одна строка = один текстовый свидетель; witness_role и authority_level обязательны
A13: Поля
A14: Поле | B14: Обязат. | C14: Тип | D14: Описание | E14: Пример | F14: Правило
A15: witness_id | B15: да | C15: string | D15: стабильный id witness-а | E15: w.ru.dionysus.translation.v1 | F15: не менять без причины
A16: language | B16: да | C16: string | D16: язык witness-а | E16: ru | F16: ISO или короткий код
A17: witness_role | B17: да | C17: enum | D17: canonical_source / working_translation / bridge_translation / agent_generated_witness | E17: working_translation | F17: роль важнее названия
A18: authority_level | B18: да | C18: enum | D18: canonical / derived_human / derived_noncanonical | E18: derived_human | F18: не завышать авторитет
A19: author_or_translator | B19: нет | C19: string | D19: автор или переводчик | E19: Dionysus | F19: если уместно
A20: edition_or_source | B20: нет | C20: string | D20: редакция или источник | E20: facsimile-backed 1883 | F20: видимая provenance
A21: publication_year | B21: нет | C21: integer | D21: год публикации | E21: 1883 | F21: если известен
A22: based_on | B22: нет | C22: string | D22: на каком witness основан | E22: w.de.nietzsche.1883.facsimile | F22: для derived слоёв
A23: normalization_note | B23: нет | C23: text | D23: что нормализовано | E23: surface cleanup pending | F23: важно для нормализации
A24: active | B24: нет | C24: boolean | D24: используется ли в текущем проходе | E24: TRUE | F24: можно отключать не удаляя
A26: Канонический пример строки
A27: witness_id | B27: language | C27: witness_role | D27: authority_level | E27: author_or_translator | F27: edition_or_source | G27: publication_year | H27: based_on | I27: normalization_note | J27: active
A28: w.ru.dionysus.translation.v1 | B28: ru | C28: working_translation | D28: derived_human | E28: Dionysus | F28: facsimile-backed 1883 | G28: 1883 | H28: w.de.nietzsche.1883.facsimile | I28: минимальная нормализация | J28: TRUE

Sheet 04_segments
A1: Схема: segments
A2: Shared paragraph-aligned spine и anchors.
A4: Таблица | B4: segments
A5: Волна | B5: фундаментальный
A6: Назначение | B6: дать общий локатор для de / ru / en и всех derived слоёв
A7: Обязательность | B7: заводить сразу
A8: Первичный ключ | B8: segment_id
A9: Зависит от | B9: corpus_map
A10: Когда спавнить | B10: новая строка на каждый segment из bounded route
A11: Правило заполнения | B11: одна строка = один общий сегмент; witness-specific тексты живут в witness surface, не здесь
A13: Поля
A14: Поле | B14: Обязат. | C14: Тип | D14: Описание | E14: Пример | F14: Правило
A15: segment_id | B15: да | C15: string | D15: стабильный id сегмента | E15: seg.1.1.1.8 | F15: один на общий segment
A16: source_secondary | B16: да | C16: string | D16: вторичный адрес | E16: 1,1,1,8 | F16: сквозной anchor
A17: paragraph_anchor | B17: да | C17: string | D17: anchor вида [n] | E17: [8] | F17: общий для свидетелей
A18: sort_key | B18: да | C18: integer | D18: порядок в route | E18: 8 | F18: строгий обход
A19: line_span | B19: нет | C19: string | D19: диапазон строк в donor file | E19: L155-L169 | F19: полезно для file-level привязки
A20: witness_scope | B20: да | C20: string | D20: какие witness-слои разделяют сегмент | E20: de+ru+en | F20: обычно общий
A21: cluster_id | B21: нет | C21: string | D21: составной кластер для multi-anchor логики | E21: cluster.descent_going_under | F21: если нужен
A22: working_name | B22: нет | C22: string | D22: рабочее имя сегмента | E22: go-under-to-humans | F22: для навигации
A23: note | B23: нет | C23: text | D23: технич. комментарий | E23: переходит в reasoning cluster | F23: без философской инфляции
A25: Канонический пример строки
A26: segment_id | B26: source_secondary | C26: paragraph_anchor | D26: sort_key | E26: witness_scope | F26: line_span | G26: cluster_id | H26: working_name | I26: note
A27: seg.1.1.1.8 | B27: 1,1,1,8 | C27: [8] | D27: 8 | E27: de+ru+en | F27: L155-L169 | G27: cluster.descent_going_under | H27: go-under-to-humans | I27: переходит в reasoning cluster

Sheet 05_nodes
A1: Схема: nodes
A2: Устойчивые сущности, символы, понятия, места.
A4: Таблица | B4: nodes
A5: Волна | B5: фундаментальный
A6: Назначение | B6: хранить переиспользуемые значения, а не фразы witness-поверхности
A7: Обязательность | B7: заводить сразу
A8: Первичный ключ | B8: node_id
A9: Зависит от | B9: segments логически; напрямую можно стартовать параллельно
A10: Когда спавнить | B10: новая строка, когда смысл становится переиспользуемым
A11: Правило заполнения | B11: одна строка = один смысл; не создавать отдельный node под каждую языковую формулировку
A13: Поля
A14: Поле | B14: Обязат. | C14: Тип | D14: Описание | E14: Пример | F14: Правило
A15: node_id | B15: да | C15: string | D15: устойчивый id узла | E15: n.underworld | F15: one meaning -> one node_id
A16: label_ru | B16: да | C16: string | D16: рабочая русская метка | E16: подземный мир | F16: для human authoring
A17: node_class | B17: да | C17: enum | D17: persona/entity/place/concept/animal-symbol/... | E17: underworld-domain | F17: тип узла
A18: layer | B18: да | C18: enum | D18: source_linked / distilled_principle / authored_commentary | E18: source_linked | F18: режим утверждения
A19: status | B19: нет | C19: enum | D19: new / reused | E19: new | F19: для контроля роста
A20: first_segment_id | B20: да | C20: string | D20: где впервые закреплен | E20: seg.1.1.1.7 | F20: первичный anchor
A21: first_source_secondary | B21: да | C21: string | D21: вторичный адрес первого появления | E21: 1,1,1,7 | F21: быстрый адрес
A22: canonical_label | B22: нет | C22: string | D22: нейтральное имя без языка поверхности | E22: underworld | F22: для экспорта
A23: label_en | B23: нет | C23: string | D23: рабочая английская метка | E23: underworld | F23: если нужна для bridge/экспорта
A24: note | B24: нет | C24: text | D24: служебная заметка | E24: адресат света солнца | F24: не заменяет principles
A26: Канонический пример строки
A27: node_id | B27: label_ru | C27: node_class | D27: layer | E27: first_segment_id | F27: first_source_secondary | G27: canonical_label | H27: label_en | I27: status | J27: note
A28: n.underworld | B28: подземный мир | C28: underworld-domain | D28: source_linked | E28: seg.1.1.1.7 | F28: 1,1,1,7 | G28: underworld | H28: underworld | I28: new | J28: адресат света солнца

Sheet 06_event_state_nodes
A1: Схема: event_state_nodes
A2: Здесь строка превращается в событие или состояние.
A4: Таблица | B4: event_state_nodes
A5: Волна | B5: фундаментальный
A6: Назначение | B6: удерживать длительность, множественных участников, условность, повторяемость и аналогии
A7: Обязательность | B7: заводить сразу
A8: Первичный ключ | B8: es_id
A9: Зависит от | B9: nodes, segments
A10: Когда спавнить | B10: когда плоская тройка теряет важную структуру
A11: Правило заполнения | B11: создавать event/state node, если у отношения есть время, путь, несколько ролей, повтор, условность или образная функция
A13: Поля
A14: Поле | B14: Обязат. | C14: Тип | D14: Описание | E14: Пример | F14: Правило
A15: es_id | B15: да | C15: string | D15: id события/состояния | E15: ev.p7_8.descent_named_as_go_under | F15: стабильный
A16: kind | B16: да | C16: enum | D16: event / state / analogy / composite | E16: event | F16: тип узла
A17: label_ru | B17: да | C17: string | D17: рабочее имя | E17: нисхождение, названное untergehen | F17: коротко и точно
A18: anchor_mode | B18: да | C18: enum | D18: single / multi | E18: multi | F18: если узел держится на 2+ сегментах
A19: anchor_start_secondary | B19: да | C19: string | D19: первый source_secondary | E19: 1,1,1,7 | F19: начало anchor
A20: anchor_end_secondary | B20: нет | C20: string | D20: последний source_secondary | E20: 1,1,1,8 | F20: если multi-anchor; для single-anchor оставлять пустым
A21: anchor_segment_ids | B21: да | C21: string | D21: shared segment spine диапазона | E21: seg.1.1.1.7|seg.1.1.1.8 | F21: pipe-list segment ids
A22: subject_hint | B22: нет | C22: string | D22: основной участник | E22: n.zarathustra | F22: подсказка, не замена edges
A23: es_class | B23: нет | C23: string | D23: класс события/состояния | E23: chosen_descent | F23: удобно для группировок
A24: repeatable | B24: нет | C24: boolean | D24: повторяется ли | E24: FALSE | F24: для ритуалов и recurring forms
A25: note | B25: нет | C25: text | D25: служебная заметка | E25: мост между [7] и [8] | F25: не заменяет principles
A27: Канонический пример строки
A28: es_id | B28: kind | C28: label_ru | D28: anchor_mode | E28: anchor_start_secondary | F28: anchor_end_secondary | G28: anchor_segment_ids | H28: subject_hint | I28: es_class | J28: repeatable | K28: note
A29: ev.p7_8.descent_named_as_go_under | B29: event | C29: нисхождение, названное untergehen | D29: multi | E29: 1,1,1,7 | F29: 1,1,1,8 | G29: seg.1.1.1.7|seg.1.1.1.8 | H29: n.zarathustra | I29: chosen_descent | J29: FALSE | K29: мост между [7] и [8]

Sheet 07_edges
A1: Схема: edges
A2: Нормализованные связи между узлами, событиями, состояниями и principles.
A4: Таблица | B4: edges
A5: Волна | B5: фундаментальный
A6: Назначение | B6: собрать графовую ткань из минимальных relations
A7: Обязательность | B7: заводить сразу
A8: Первичный ключ | B8: edge_id
A9: Зависит от | B9: nodes, event_state_nodes и principles
A10: Когда спавнить | B10: новая строка на каждую устойчивую relation
A11: Правило заполнения | B11: не хранить в одной строке два разных утверждения; complex logic выносить в event/state/principle nodes
A13: Поля
A14: Поле | B14: Обязат. | C14: Тип | D14: Описание | E14: Пример | F14: Правило
A15: edge_id | B15: да | C15: string | D15: id связи | E15: e63 | F15: стабилен внутри проекта
A16: edge_kind | B16: да | C16: enum | D16: source_edge / bridge_edge / principle_edge | E16: source_edge | F16: row-kind relation
A17: from_id | B17: да | C17: string | D17: исходный id | E17: n.humans | F17: node_id / es_id / principle_id
A18: predicate_id | B18: да | C18: string | D18: нормализованный предикат | E18: names_descent_as | F18: не языковая поверхность
A19: to_id | B19: да | C19: string | D19: целевой id | E19: n.go_under | F19: node_id / es_id / principle_id
A20: layer | B20: да | C20: enum | D20: source_linked / distilled_principle / authored_commentary | E20: source_linked | F20: режим утверждения
A21: anchor_mode | B21: да | C21: enum | D21: single / multi | E21: single | F21: единый anchor contract
A22: anchor_start_secondary | B22: да | C22: string | D22: начало привязки к месту | E22: 1,1,1,8 | F22: минимальный anchor
A23: anchor_end_secondary | B23: нет | C23: string | D23: конец привязки | E23: 1,1,1,8 | F23: для multi-anchor; для single-anchor оставлять пустым
A24: anchor_segment_ids | B24: да | C24: string | D24: привязка к spine сегментов | E24: seg.1.1.1.8 | F24: single value тоже здесь
A25: witness_scope | B25: нет | C25: string | D25: какие witness-слои подтверждают | E25: de+ru+en | F25: или конкретный witness
... A28: note | B28: нет | C28: text | D28: служебная помета | E28: люди дают имя нисхождению | F28: без инфляции
A30: Канонический пример строки
A31: edge_id | B31: edge_kind | C31: from_id | D31: predicate_id | E31: to_id | F31: layer | G31: anchor_mode | H31: anchor_start_secondary | I31: anchor_end_secondary | J31: anchor_segment_ids | K31: witness_scope | L31: connectivity_role | M31: confidence | N31: note
A32: e63 | B32: source_edge | C32: n.humans | D32: names_descent_as | E32: n.go_under | F32: source_linked | G32: single | H32: 1,1,1,8 | J32: seg.1.1.1.8 | K32: de+ru+en | L32: local_chain | M32: 1 | N32: люди дают имя нисхождению

Sheet 08_translation_tensions
A1: Схема: translation_tensions
A2: Только philosophically load-bearing drift clusters.
A4: Таблица | B4: translation_tensions
A5: Волна | B5: фундаментальный+
A6: Назначение | B6: фиксировать места, где drift между witness-слоями реально меняет вес мысли
A7: Обязательность | B7: заводить сразу, но скупо
A8: Первичный ключ | B8: tension_id
A9: Зависит от | B9: segments, witnesses, witness_glosses
A10: Когда спавнить | B10: когда drift нельзя честно спрятать в обычную нормализацию
A11: Правило заполнения | B11: не превращать в склад всех различий; только нагрузочные швы
A13: Поля
A14: Поле | B14: Обязат. | C14: Тип | D14: Описание | E14: Пример | F14: Правило
A15: tension_id | B15: да | C15: string | D15: id tension-а | E15: tt.untergehen | F15: стабилен
A16: normalized_core | B16: да | C16: string | D16: какое ядро tension держит | E16: go_under | F16: не wide bundle surface-ов
A17: anchor_mode | B17: да | C17: enum | D17: single / multi | E17: multi | F17: единый anchor contract
A18: anchor_start_secondary | B18: да | C18: string | D18: первый адрес tension-а | E18: 1,1,1,7 | F18: начало диапазона
A19: anchor_end_secondary | B19: нет | C19: string | D19: последний адрес tension-а | E19: 1,1,1,8 | F19: если multi-anchor; для single-anchor оставлять пустым
A20: anchor_segment_ids | B20: да | C20: string | D20: segment spine tension-а | E20: seg.1.1.1.7|seg.1.1.1.8 | F20: pipe-list segment ids
A21: witness_ids | B21: нет | C21: string | D21: какие witness участвуют в tension-е | E21: w.de...|w.ru...|w.en... | F21: если нужно явное перечисление
A22: why_load_bearing | B22: да | C22: text | D22: почему это важно | E22: человеческое имя нисхождения, не поражение | F22: обязательно объяснить
A23: decision_status | B23: нет | C23: enum | D23: open / bounded / stabilized | E23: bounded | F23: степень фиксации
A24: preferred_handling | B24: нет | C24: text | D24: как обращаться с drift | E24: держать tension видимым | F24: рабочее решение
A25: note | B25: нет | C25: text | D25: служебная помета | E25: surface rows живут в glosses | F25: не дублировать wide bundle
A26: Канонический пример строки
A27: tension_id | B27: normalized_core | C27: anchor_mode | D27: anchor_start_secondary | E27: anchor_end_secondary | F27: anchor_segment_ids | G27: witness_ids | H27: why_load_bearing | I27: decision_status | J27: preferred_handling | K27: note
A28: tt.untergehen | B28: go_under | C28: multi | D28: 1,1,1,7 | E28: 1,1,1,8 | F28: seg.1.1.1.7|seg.1.1.1.8 | G28: w.de.nietzsche.1883.facsimile|w.ru.dionysus.translation.v1|w.en.bridge.translation.v1 | H28: узловой термин нисхождения и его людского имени | I28: bounded | J28: держать tension видимым | K28: surface rows живут в glosses

Sheet 09_witness_glosses
A1: Схема: witness_glosses
A2: Witness-specific long-model слой для лексической поверхности.
A4: Таблица | B4: witness_glosses
A5: Волна | B5: вторая волна
A6: Назначение | B6: сохранять точные witness-specific формулировки там, где они не должны растворяться
A7: Обязательность | B7: по мере сгущения
A8: Первичный ключ | B8: gloss_id
A9: Зависит от | B9: witnesses, segments, translation_tensions
A10: Когда спавнить | B10: когда формулировка сама по себе значима
A11: Правило заполнения | B11: одна строка = одна witness-specific поверхность; не превращать gloss в самостоятельный concept без нужды
A13: Поля
A14: Поле | B14: Обязат. | C14: Тип | D14: Описание | E14: Пример | F14: Правило
A15: gloss_id | B15: да | C15: string | D15: id gloss-а | E15: g.1.enjoyment | F15: стабилен
A16: witness_id | B16: да | C16: string | D16: какому witness принадлежит | E16: w.ru.dionysus.translation.v1 | F16: явная provenance
A17: segment_id | B17: да | C17: string | D17: где встречается | E17: seg.1.1.1.1 | F17: anchor
A18: source_secondary | B18: да | C18: string | D18: вторичный адрес | E18: 1,1,1,1 | F18: быстрый anchor
A19: token_or_phrase | B19: да | C19: string | D19: буквальная поверхность | E19: вкушал | F19: то, что нельзя потерять
A20: normalized_core | B20: да | C20: string | D20: какое ядро стоит за ней | E20: delights_in | F20: смысловое ядро
A21: tension_id | B21: нет | C21: string | D21: к какому tension привязан gloss | E21: tt.untergehen | F21: если gloss участвует в drift-cluster
A22: gloss_note | B22: нет | C22: text | D22: что эта поверхность усиливает | E22: телесность внутреннего вкушения | F22: коротко
A23: status | B23: нет | C23: enum | D23: open / useful / stabilized | E23: useful | F23: рабочий статус
A24: Канонический пример строки
A25: gloss_id | B25: witness_id | C25: segment_id | D25: source_secondary | E25: token_or_phrase | F25: normalized_core | G25: tension_id | H25: gloss_note | I25: status
A26: g.1.enjoyment | B26: w.ru.dionysus.translation.v1 | C26: seg.1.1.1.1 | D26: 1,1,1,1 | E26: вкушал | F26: delights_in | G26: tt.untergehen | H26: телесность внутреннего вкушения | I26: useful

Sheet 10_principles
A1: Схема: principles
A2: Distilled principles и authored commentary поверх anchors.
A4: Таблица | B4: principles
A5: Волна | B5: вторая волна
A6: Назначение | B6: фиксировать уже снятые принципы, не выдавая их за буквальный source fact
A7: Обязательность | B7: по мере сгущения
A8: Первичный ключ | B8: principle_id
A9: Зависит от | B9: segments, nodes, event_state_nodes, edges
A10: Когда спавнить | B10: когда место уже удерживает принцип, а не только событие
A11: Правило заполнения | B11: принцип должен иметь anchor и layer; его support нормализуется через principle_edge rows в edges
A13: Поля
A14: Поле | B14: Обязат. | C14: Тип | D14: Описание | E14: Пример | F14: Правило
A15: principle_id | B15: да | C15: string | D15: id принципа | E15: pr.descent_is_required_by_gift | F15: стабилен
A16: layer | B16: да | C16: enum | D16: distilled_principle / authored_commentary | E16: distilled_principle | F16: режим утверждения
A17: formula_ru | B17: да | C17: text | D17: сжатая формула принципа | E17: подлинный дар требует нисхождения | F17: коротко и ясно
A18: anchor_mode | B18: да | C18: enum | D18: single / multi | E18: multi | F18: единый anchor contract
A19: anchor_start_secondary | B19: да | C19: string | D19: первый адрес | E19: 1,1,1,6 | F19: начало опоры
A20: anchor_end_secondary | B20: нет | C20: string | D20: последний адрес | E20: 1,1,1,7 | F20: если multi-anchor; для single-anchor оставлять пустым
A21: anchor_segment_ids | B21: да | C21: string | D21: сегменты опоры | E21: seg.1.1.1.6|seg.1.1.1.7 | F21: pipe-list segment ids
A22: status | B22: нет | C22: enum | D22: open / bounded / stabilized | E22: bounded | F22: степень фиксации
A23: note | B23: нет | C23: text | D23: служебная помета | E23: не выдавать за source fact | F23: если нужно
A25: Канонический пример строки
A26: principle_id | B26: layer | C26: formula_ru | D26: anchor_mode | E26: anchor_start_secondary | F26: anchor_end_secondary | G26: anchor_segment_ids | H26: status | I26: note
A27: pr.descent_is_required_by_gift | B27: distilled_principle | C27: подлинный дар требует нисхождения | D27: multi | E27: 1,1,1,6 | F27: 1,1,1,7 | G27: seg.1.1.1.6|seg.1.1.1.7 | H27: bounded | I27: не выдавать за source fact

Sheet 11_Рост_и_спавн
A1: Правила спавна новых таблиц
A2: Когда создавать новую таблицу, а когда не создавать.
A4: Таблица | B4: growth_rules
A5: Волна | B5: мета-слой
A6: Назначение | B6: не дать проекту распухнуть и в то же время не зажать рост
A7: Обязательность | B7: держать рядом с самого начала
A8: Первичный ключ | B8: rule_id
A9: Зависит от | B9: весь проект
A10: Когда спавнить | B10: не спавнится; это регулятор
A11: Правило заполнения | B11: каждая новая таблица должна пройти тест пользы
A13: Поля
A14: Поле | B14: Обязат. | C14: Тип | D14: Описание | E14: Пример | F14: Правило
A15: rule_id | B15: да | C15: string | D15: id правила | E15: gr.01 | F15: технический
A16: question | B16: да | C16: text | D16: контрольный вопрос | E16: Открывает ли новая таблица новый тип запроса? | F16: задает тест
A17: yes_action | B17: да | C17: text | D17: что делать если да | E17: заводить таблицу и связывать через устойчивые ids | F17: позитивный ход
A18: no_action | B18: да | C18: text | D18: что делать если нет | E18: оставить данные в существующей таблице | F18: не плодить лишнее
A19: danger | B19: нет | C19: text | D19: чего избегать | E19: дублирование узлов и смешение source/commentary | F19: красная зона
A21: Минимальный пример строки
A22: rule_id | B22: question | C22: yes_action | D22: no_action | E22: danger
A23: gr.01 | B23: Открывает ли новая таблица новый тип запроса или reasoning path? | C23: Да: создать новую таблицу. | D23: Нет: оставить в текущем слое. | E23: Пустое размножение схем.
A24: gr.02 | B24: Снимает ли она путаницу между witness, layer и provenance? | C24: Да: создать новую таблицу. | D24: Нет: уточнить текущие поля. | E24: Смешение происхождения и толкования.
A25: gr.03 | B25: Снижает ли она дублирование? | C25: Да: нормализовать и вынести. | D25: Нет: не спавнить. | E25: Параллельные копии одного смысла.
A26: gr.04 | B26: Становится ли аналогия сама queryable? | C26: Да: позже создать analogy_nodes. | D26: Нет: оставить kind=analogy в event_state_nodes. | E26: Преждевременная инфляция символов.

Sheet 12_Sources
A1: Источники схемы
A2: Plain text URLs для проектной дисциплины
A4: Источник | B4: URL | C4: Зачем нужен
A5: ToS Charter | B5: https://raw.githubusercontent.com/8Dionysus/Tree-of-Sophia/main/CHARTER.md | C5: raw material, derived extraction и human-reviewed synthesis должны быть разведены; growth through explicit structure.
A6: Zarathustra Trilingual Entry | B6: https://raw.githubusercontent.com/8Dionysus/Tree-of-Sophia/main/docs/ZARATHUSTRA_TRILINGUAL_ENTRY.md | C6: 1 source node, 12 shared paragraph-aligned segments, 3 language witnesses, bounded translation_tensions, deepening not widening.
A7: source_node.example.json | B7: https://raw.githubusercontent.com/8Dionysus/Tree-of-Sophia/main/examples/source_node.example.json | C7: interpretation_layers = source_linked / distilled_thesis / commentary; key_terms include solitude, overflow, descent, return.
A8: Audit patchpack | B8: user-uploaded workbook: tos_kag_project_scheme_v5_patchpack.xlsx | C8: канонический контракт, patch-list и seed-реестры для v6

Sheet 13_Проектная_схема
A1: Проектная схема ToS/KAG v6.1
A2: Стартовый набор authoring tables, governance-слой и generated serving views
A4: Назначение | B4: Дать одну рабочую карту проекта: с каких таблиц начинать, что в них обязательно, что можно отложить и когда рождать следующий слой.
A5: Главный принцип | B5: Малое устойчивое ядро сначала; новые таблицы только тогда, когда они открывают новый тип запроса, удерживают provenance, снимают путаницу или закрепляют governance.
A6: Authoring vs serving | B6: corpus_map / witnesses / segments / nodes / event_state_nodes / principles / edges / tensions / glosses = authoring. master_view / coverage_view / actual layers = serving.
A7: Базовый старт | B7: corpus_map, witnesses, segments, nodes, event_state_nodes, edges, translation_tensions.
A8: Вторая волна | B8: witness_glosses, principles, predicates_registry, class_registry.
A9: Третья волна | B9: reasoning_paths, lineage_links, agent_witnesses, query_views, поздние symbolic projections.
A11: Таблица | B11: Роль | C11: Обязательные поля | D11: Опциональные поля | E11: Заполнять когда | F11: Правило заполнения | G11: Не делать | H11: Спавнить дальше когда | I11: Минимальный пример
A12: corpus_map | B12: authoring / base | C12: corpus_row_id; work_id; part_no; chapter_no; subchapter_no; paragraph_no; source_secondary; sort_key | D12: title_ru; title_en; note | E12: сразу | F12: Одна строка = одно адресуемое место корпуса. | G12: Не превращать corpus_map в таблицу смыслов. | H12: Когда нужен стабильный адрес книги/главы/части/абзаца. | I12: cm.1.1.1.8 | 1,1,1,8 | 8
A13: witnesses | B13: authoring / base | C13: witness_id; language; witness_role; authority_level | D13: author_or_translator; edition_or_source; publication_year; based_on; normalization_note; active | E13: сразу | F13: Одна строка = один text witness. | G13: Не смешивать witness и layer. | H13: Когда есть 2+ text layers или нужен provenance. | I13: w.ru.dionysus.translation.v1
A14: segments | B14: authoring / base | C14: segment_id; source_secondary; paragraph_anchor; sort_key; witness_scope | D14: line_span; cluster_id; working_name; note | E14: сразу после разметки | F14: Одна строка = один shared paragraph-aligned segment. | G14: Не путать segment spine с witness surface. | H14: Когда нужен общий anchor для всех слоёв. | I14: seg.1.1.1.5
A15: nodes | B15: authoring / base | C15: node_id; label_ru; node_class; layer; first_segment_id; first_source_secondary | D15: canonical_label; label_en; status; note | E15: сразу после первых segments | F15: Один смысл -> один node_id. | G15: Не плодить языковые копии смысла. | H15: Когда смысл должен переиспользоваться. | I15: n.overflow
A16: event_state_nodes | B16: authoring / base | C16: es_id; kind; label_ru; anchor_mode; anchor_start_secondary; anchor_segment_ids | D16: anchor_end_secondary; subject_hint; es_class; repeatable; note | E16: когда тройка тесна | F16: Выносить длительность, повторяемость, условность, множественных участников и analogies. | G16: Не делать event/state из каждой простой тройки. | H16: Когда relation несёт собственную структуру. | I16: st.p1.solitary_ripening_10y
A17: edges | B17: authoring / base | C17: edge_id; edge_kind; from_id; predicate_id; to_id; layer; anchor_mode; anchor_start_secondary; anchor_segment_ids | D17: anchor_end_secondary; witness_scope; connectivity_role; confidence; note | E17: сразу после nodes и es | F17: Edges связывают node/es/principle ids. | G17: Не писать смысл прямо в master. | H17: Когда есть хотя бы один нормализованный id. | I17: e63
A18: translation_tensions | B18: authoring / base+ | C18: tension_id; normalized_core; anchor_mode; anchor_start_secondary; anchor_segment_ids; why_load_bearing | D18: anchor_end_secondary; witness_ids; decision_status; preferred_handling; note | E18: сразу, но скупо | F18: Только load-bearing drift clusters. | G18: Не хранить здесь wide tri-lingual bundles. | H18: Когда drift меняет философский вес. | I18: tt.untergehen
A19: witness_glosses | B19: authoring / wave2 | C19: gloss_id; witness_id; segment_id; source_secondary; token_or_phrase; normalized_core | D19: tension_id; gloss_note; status | E19: по мере сгущения | F19: Gloss = one witness-specific lexical surface. | G19: Не превращать glosses в словарную свалку. | H19: Когда формулировка сама ведёт смысл. | I19: g.1.enjoyment
A20: principles | B20: authoring / wave2 | C20: principle_id; layer; formula_ru; anchor_mode; anchor_start_secondary; anchor_segment_ids | D20: anchor_end_secondary; status; note | E20: по мере сгущения | F20: Support нормализуется через principle_edge rows. | G20: Не держать supporting_ids pipe-list внутри principle row. | H20: Когда edges уже снимаются в общий закон. | I20: pr.happiness_is_relational
A21: predicates_registry | B21: governance / wave2 | C21: predicate_id; predicate_ru | D21: inverse_predicate_id; allowed_from_classes; allowed_to_classes; status; note | E21: когда растёт словарь предикатов | F21: Реестр управляет predicate drift. | G21: Не плодить близкие глаголы без решения registry. | H21: Когда master накапливает singletons и почти-дубли. | I21: addresses
A22: class_registry | B22: governance / wave2 | C22: class_id | D22: family; parent_class; status; note | E22: когда растёт словарь классов | F22: Реестр управляет class drift. | G22: Не создавать новый class label без сверки. | H22: Когда классы начинают расползаться. | I22: event
... A24: coverage_view | B24: serving / generated | C24: generated from master_view | D24: counts by row_kind / layer / connectivity_role | E24: после master_view | F24: Динамический аудит покрытия. | G24: Не держать fixed ranges, которые тихо врут при росте. | H24: Когда нужен быстрый контроль охвата. | I24: 16_Master_покрытие_1_12
A26: Serving-проекции
A27: 17_nodes_actual | B27: Чистая фактическая проекция n.* узлов из master
A28: 18_event_state_nodes_actual | B28: Чистая фактическая проекция ev.* и st.* узлов из master
A29: 19_principles_actual | B29: Чистая фактическая проекция principle-слоя из master

Sheet 14_Порядок_прохода
A1: Порядок прохода по книге
A2: Как проходить корпус волнами: от адреса и witness-слоя до principles, principle edges и generated serving views
A4: Режим работы | B4: Сначала горизонтальная волна: покрыть корпус простыми и устойчивыми таблицами. Потом вертикальная волна: углублять плотные места и подключать governance.
A5: Тактическое правило | B5: Не ждать идеальной системы. Заполнять ядро широко, а сложные таблицы рождать по триггерам.
A6: Практический ритм | B6: Новый фрагмент -> corpus_map -> witnesses -> segments -> nodes -> event_state_nodes -> source/bridge edges -> translation_tensions -> witness_glosses -> principles -> principle edges -> generated master -> coverage/actual views.
A9: Шаг | B9: Волна | C9: Что делаем | D9: Какие таблицы трогаем | E9: Минимальный результат | F9: Стоп-условие | G9: Что рождаем потом
A10: 1 | B10: горизонтальная | C10: Заводим адрес корпуса | D10: corpus_map | E10: У каждого нового куска есть source_secondary и sort_key | F10: Адрес стабилен и не плавает | G10: witnesses
A11: 2 | B11: горизонтальная | C11: Фиксируем текстовых свидетелей | D11: witnesses | E11: Понятно, кто canonical, кто working_translation, кто bridge | F11: У каждого текста есть witness_id и witness_role | G11: segments
A12: 3 | B12: горизонтальная | C12: Режем на shared segments | D12: segments | E12: Есть spine: paragraph_anchor, segment_id, witness_scope | F12: Можно сослаться на любой кусок текста | G12: nodes
A13: 4 | B13: горизонтальная | C13: Выделяем переиспользуемые узлы | D13: nodes | E13: Сущности, места, символы, понятия получили node_id | F13: Нет лишних дублей смыслов | G13: event_state_nodes
A14: 5 | B14: горизонтальная | C14: Выделяем события и состояния | D14: event_state_nodes | E14: Сложные строки получили es_id и explicit anchor contract | F14: Тройки больше не ломаются на простоте | G14: edges
A15: 6 | B15: горизонтальная | C15: Строим source/bridge relations | D15: edges | E15: Есть базовый граф и anchors | F15: Можно собрать минимальный reasoning path | G15: translation_tensions
A16: 7 | B16: горизонтальная+ | C16: Фиксируем нагрузочные дрейфы перевода | D16: translation_tensions | E16: Пойманы только философски значимые tension points | F16: Нет шума из мелкой стилистики | G16: witness_glosses или следующий фрагмент
A17: 8 | B17: вертикальная | C17: Сохраняем лексические поверхности | D17: witness_glosses | E17: Есть long-model gloss rows | F17: Glosses работают как мост к witness-форме | G17: principles
A18: 9 | B18: вертикальная | C18: Снимаем принципы и commentary | D18: principles | E18: Есть distilled principles и authored commentary | F18: Принципы не маскируются под source fact | G18: principle edges
A19: 10 | B19: вертикальная | C19: Нормализуем поддержку принципов как edges | D19: edges (principle_edge) | E19: Support живет в графе, а не в pipe-list inside principles | F19: Связи queryable и не дублируются | G19: generated master
A20: 11 | B20: serving | C20: Генерируем denormalized relation view | D20: master_view | E20: Есть единая master-таблица для чтения, аудита и экспорта | F20: Master не используется как hidden truth-sheet | G20: coverage_view / actual layers
A21: 12 | B21: serving | C21: Строим аудит покрытия и фактические проекции | D21: coverage_view; actual layers; registries | E21: Есть проверка охвата, реестры governance и чистые projections | F21: Проекции не подменяют source-first authoring | G21: следующий виток корпуса
A23: Трасса генерации v6.1
A24: Стадия | B24: Вход | C24: Выход | D24: Правило
A25: authoring_base | B25: 02_corpus_map; 03_witnesses; 04_segments; 05_nodes; 06_event_state_nodes; 07_edges; 08_translation_tensions; 09_witness_glosses; 10_principles | C25: 15_Master_связность_1_12 | D25: master_view генерируется как denormalized serving layer; в него не авторят вручную
A26: master_view | B26: 15_Master_связность_1_12 | C26: 16_Master_покрытие_1_12 | D26: coverage_view считает охват, row_kind, layer и paragraph spans поверх generated master
A27: master_view + registries | B27: 15_Master_связность_1_12; 20_predicates_registry; 21_class_registry | C27: 17_nodes_actual; 18_event_state_nodes_actual; 19_principles_actual | D27: actual-projections читают факты из master, а registries стабилизируют словари

Sheet 15_Master_связность_1_12
A1: Master_view (generated serving layer) по [1]-[12]
A2: DO NOT AUTHOR HERE. Этот лист генерируется из authoring tables и служит для чтения, аудита и экспорта.
A4: Назначение | B4: Свести в одном месте source, bridge и principle relations по [1]-[12] как serving view.
A5: Всего строк | B5: =COUNTA(A12:A5000)
A6: source_edge | B6: =COUNTIF(B12:B5000,"source_edge")
A7: bridge_edge | B7: =COUNTIF(B12:B5000,"bridge_edge")
A8: principle_edge | B8: =COUNTIF(B12:B5000,"principle_edge")
A9: Как читать | B9: Фильтруй по row_kind, layer, p_start/p_end, paragraph_tags и connectivity_role; authoring ведется в base sheets, не здесь.
A11: master_id | B11: row_kind | C11: from_id | D11: from_label_ru | E11: from_class | F11: predicate_id | G11: predicate_ru | H11: to_id | I11: to_label_ru | J11: to_class | K11: layer | L11: source_secondary_start | M11: source_secondary_end | N11: p_start | O11: p_end | P11: n_range | Q11: paragraph_tags | R11: segment_ids | S11: witness_scope | T11: connectivity_role | U11: note_ru
A12: m001 | B12: source_edge | C12: n.zarathustra | D12: Заратустра | E12: persona | F12: participates_in | G12: участвует в | H12: ev.p1.departure_from_origin | I12: уход из родины и озера | J12: event | K12: source_linked | L12: 1,1,1,1 | N12: 1 | O12: 1 | P12: [1] | Q12: |p1| | R12: seg.1.1.1.1 | S12: de+ru+en | T12: local_chain | U12: стартовый пространственный разрыв
A13: m002 | B13: source_edge | C13: ev.p1.departure_from_origin | D13: уход из родины и озера | E13: event | F13: leaves | G13: покидает | H13: n.homeland | I13: родина | J13: place | K13: source_linked | L13: 1,1,1,1 | N13: 1 | O13: 1 | P13: [1] | Q13: |p1| | R13: seg.1.1.1.1 | S13: de+ru+en | T13: local_chain
A14: m003 | B14: source_edge | C14: ev.p1.departure_from_origin | D14: уход из родины и озера | E14: event | F14: leaves | G14: покидает | H14: n.lake_of_homeland | I14: озеро родины | J14: place-symbol | K14: source_linked | L14: 1,1,1,1 | N14: 1 | O14: 1 | P14: [1] | Q14: |p1| | R14: seg.1.1.1.1 | S14: de+ru+en | T14: local_chain
A15: m004 | B15: source_edge | C15: ev.p1.departure_from_origin | D15: уход из родины и озера | E15: event | F15: goes_to | G15: идёт в | H15: n.mountains | I15: горы | J15: place | K15: source_linked | L15: 1,1,1,1 | N15: 1 | O15: 1 | P15: [1] | Q15: |p1| | R15: seg.1.1.1.1 | S15: de+ru+en | T15: local_chain
A16: m005 | B16: source_edge | C16: n.zarathustra | D16: Заратустра | E16: persona | F16: enters_state | G16: входит в состояние | H16: st.p1.solitary_ripening_10y | I16: десятилетнее горное уединение | J16: state | K16: source_linked | L16: 1,1,1,1 | N16: 1 | O16: 1 | P16: [1] | Q16: |p1| | R16: seg.1.1.1.1 | S16: de+ru+en | T16: local_chain | U16: десятилетнее уединение как состояние
A17: m006 | B17: source_edge | C17: st.p1.solitary_ripening_10y | D17: десятилетнее горное уединение | E17: state | F17: delights_in | G17: вкушает / наслаждается | H17: n.spirit | I17: дух | J17: inner_resource | K17: source_linked | L17: 1,1,1,1 | N17: 1 | O17: 1 | P17: [1] | Q17: |p1| | R17: seg.1.1.1.1 | S17: de+ru+en | T17: local_chain
A18: m007 | B18: source_edge | C18: st.p1.solitary_ripening_10y | D18: десятилетнее горное уединение | E18: state | F18: delights_in | G18: вкушает / наслаждается | H18: n.solitude | I18: одиночество / уединение | J18: state-concept | K18: source_linked | L18: 1,1,1,1 | N18: 1 | O18: 1 | P18: [1] | Q18: |p1| | R18: seg.1.1.1.1 | S18: de+ru+en | T18: local_chain
A19: m008 | B19: source_edge | C19: st.p1.solitary_ripening_10y | D19: десятилетнее горное уединение | E19: state | F19: duration | G19: имеет длительность | H19: literal.ten_years | I19: десять лет | J19: literal | K19: source_linked | L19: 1,1,1,1 | N19: 1 | O19: 1 | P19: [1] | Q19: |p1| | R19: seg.1.1.1.1 | S19: de+ru+en | T19: local_chain
A20: m009 | B20: bridge_edge | C20: st.p1.solitary_ripening_10y | D20: десятилетнее горное уединение | E20: state | F20: leads_to | G20: ведёт к | H20: ev.p1.heart_transformation | I20: преображение сердца | J20: event | K20: source_linked | L20: 1,1,1,1 | N20: 1 | O20: 1 | P20: [1] | Q20: |p1| | R20: seg.1.1.1.1 | S20: de+ru+en | T20: reasoning_bridge | U20: созревание ведет к внутреннему повороту
A21: m010 | B21: source_edge | C21: ev.p1.heart_transformation | D21: преображение сердца | E21: event | F21: affects | G21: затрагивает | H21: n.heart | I21: сердце | J21: inner_center | K21: source_linked | L21: 1,1,1,1 | N21: 1 | O21: 1 | P21: [1] | Q21: |p1| | R21: seg.1.1.1.1 | S21: de+ru+en | T21: local_chain
A22: m011 | B22: bridge_edge | C22: ev.p1.heart_transformation | D22: преображение сердца | E22: event | F22: prepares | G22: подготавливает | H22: ev.p1.dawn_address_to_sun | I22: утреннее обращение к солнцу | J22: event | K22: source_linked | L22: 1,1,1,1 | N22: 1 | O22: 1 | P22: [1] | Q22: |p1| | R22: seg.1.1.1.1 | S22: de+ru+en | T22: reasoning_bridge
A23: m012 | B23: source_edge | C23: n.zarathustra | D23: Заратустра | E23: persona | F23: performs | G23: совершает | H23: ev.p1.dawn_address_to_sun | I23: утреннее обращение к солнцу | J23: event | K23: source_linked | L23: 1,1,1,1 | N23: 1 | O23: 1 | P23: [1] | Q23: |p1| | R23: seg.1.1.1.1 | S23: de+ru+en | T23: local_chain
A24: m013 | B24: source_edge | C24: ev.p1.dawn_address_to_sun | D24: утреннее обращение к солнцу | E24: event | F24: occurs_with | G24: происходит вместе с | H24: n.dawn | I24: заря | J24: time-symbol | K24: source_linked | L24: 1,1,1,1 | N24: 1 | O24: 1 | P24: [1] | Q24: |p1| | R24: seg.1.1.1.1 | S24: de+ru+en | T24: local_chain
A25: m014 | B25: source_edge | C25: ev.p1.dawn_address_to_sun | D25: утреннее обращение к солнцу | E25: event | F25: addresses | G25: обращается к | H25: n.sun | I25: солнце / великое светило | J25: cosmic_entity | K25: source_linked | L25: 1,1,1,1 | N25: 1 | O25: 1 | P25: [1] | Q25: |p1| | R25: seg.1.1.1.1 | S25: de+ru+en | T25: local_chain
A26: m015 | B26: source_edge | C26: n.sun | D26: солнце / великое светило | E26: cosmic_entity | F26: participates_in | G26: участвует в | H26: st.p2.solar_happiness_requires_recipients | I26: счастье светила требует адресатов света | J26: state | K26: source_linked | L26: 1,1,1,2 | N26: 2 | O26: 2 | P26: [2] | Q26: |p2| | R26: seg.1.1.1.2 | S26: de+ru+en | T26: local_chain | U26: солнечное счастье задано как отношение
A27: m016 | B27: source_edge | C27: st.p2.solar_happiness_requires_recipients | D27: счастье светила требует адресатов света | E27: state | F27: concerns | G27: касается | H27: n.happiness | I27: счастье | J27: quality | K27: source_linked | L27: 1,1,1,2 | N27: 2 | O27: 2 | P27: [2] | Q27: |p2| | R27: seg.1.1.1.2 | S27: de+ru+en | T27: local_chain
A28: m017 | B28: source_edge | C28: n.happiness | D28: счастье | E28: quality | F28: depends_on | G28: зависит от | H28: n.recipients_of_light | I28: те, кому светят | J28: relational_group | K28: source_linked | L28: 1,1,1,2 | N28: 2 | O28: 2 | P28: [2] | Q28: |p2| | R28: seg.1.1.1.2 | S28: de+ru+en | T28: local_chain
A29: m018 | B29: source_edge | C29: st.p2.solar_happiness_requires_recipients | D29: счастье светила требует адресатов света | E29: state | F29: targets | G29: направлено к | H29: n.recipients_of_light | I29: те, кому светят | J29: relational_group | K29: source_linked | L29: 1,1,1,2 | N29: 2 | O29: 2 | P29: [2] | Q29: |p2| | R29: seg.1.1.1.2 | S29: de+ru+en | T29: local_chain | U29: адресаты света держат смысл счастья
A30: m019 | B30: source_edge | C30: n.sun | D30: солнце / великое светило | E30: cosmic_entity | F30: participates_in | G30: участвует в | H30: ev.p3.sun_ascends_to_cave_10y | I30: десятилетнее восхождение солнца к пещере | J30: event | K30: source_linked | L30: 1,1,1,3 | N30: 3 | O30: 3 | P30: [3] | Q30: |p3| | R30: seg.1.1.1.3 | S30: de+ru+en | T30: local_chain
A31: m020 | B31: source_edge | C31: ev.p3.sun_ascends_to_cave_10y | D31: десятилетнее восхождение солнца к пещере | E31: event | F31: destination | G31: направляется в | H31: n.cave | I31: пещера | J31: place-threshold | K31: source_linked | L31: 1,1,1,3 | N31: 3 | O31: 3 | P31: [3] | Q31: |p3| | R31: seg.1.1.1.3 | S31: de+ru+en | T31: local_chain
A32: m021 | B32: source_edge | C32: ev.p3.sun_ascends_to_cave_10y | D32: десятилетнее восхождение солнца к пещере | E32: event | F32: duration | G32: имеет длительность | H32: literal.ten_years | I32: десять лет | J32: literal | K32: source_linked | L32: 1,1,1,3 | N32: 3 | O32: 3 | P32: [3] | Q32: |p3| | R32: seg.1.1.1.3 | S32: de+ru+en | T32: local_chain
A33: m022 | B33: source_edge | C33: n.sun | D33: солнце / великое светило | E33: cosmic_entity | F33: participates_in | G33: участвует в | H33: st.p3.sun_would_grow_sated_without_triad | I33: без триады солнце пресытилось бы светом и путем | J33: state | K33: source_linked | L33: 1,1,1,3 | N33: 3 | O33: 3 | P33: [3] | Q33: |p3| | R33: seg.1.1.1.3 | S33: de+ru+en | T33: local_chain | U33: условная конструкция пресыщения
A34: m023 | B34: source_edge | C34: st.p3.sun_would_grow_sated_without_triad | D34: без триады солнце пресытилось бы светом и путем | E34: state | F34: concerns | G34: касается | H34: n.light | I34: свет | J34: quality-substance | K34: source_linked | L34: 1,1,1,3 | N34: 3 | O34: 3 | P34: [3] | Q34: |p3| | R34: seg.1.1.1.3 | S34: de+ru+en | T34: local_chain
A35: m024 | B35: source_edge | C35: st.p3.sun_would_grow_sated_without_triad | D35: без триады солнце пресытилось бы светом и путем | E35: state | F35: concerns | G35: касается | H35: n.path | I35: путь | J35: route | K35: source_linked | L35: 1,1,1,3 | N35: 3 | O35: 3 | P35: [3] | Q35: |p3| | R35: seg.1.1.1.3 | S35: de+ru+en | T35: local_chain
A36: m025 | B36: source_edge | C36: st.p3.sun_would_grow_sated_without_triad | D36: без триады солнце пресытилось бы светом и путем | E36: state | F36: prevented_by | G36: предотвращается через | H36: n.triad_zarathustra_eagle_serpent | I36: Заратустра + орёл + змея | J36: collective_subject | K36: source_linked | L36: 1,1,1,3 | N36: 3 | O36: 3 | P36: [3] | Q36: |p3| | R36: seg.1.1.1.3 | S36: de+ru+en | T36: local_chain
A37: m026 | B37: source_edge | C37: n.triad_zarathustra_eagle_serpent | D37: Заратустра + орёл + змея | E37: collective_subject | F37: includes | G37: включает | H37: n.zarathustra | I37: Заратустра | J37: persona | K37: source_linked | L37: 1,1,1,3 | N37: 3 | O37: 3 | P37: [3] | Q37: |p3| | R37: seg.1.1.1.3 | S37: de+ru+en | T37: local_chain
A38: m027 | B38: source_edge | C38: n.triad_zarathustra_eagle_serpent | D38: Заратустра + орёл + змея | E38: collective_subject | F38: includes | G38: включает | H38: n.eagle | I38: орёл | J38: animal-symbol | K38: source_linked | L38: 1,1,1,3 | N38: 3 | O38: 3 | P38: [3] | Q38: |p3| | R38: seg.1.1.1.3 | S38: de+ru+en | T38: local_chain
A39: m028 | B39: source_edge | C39: n.triad_zarathustra_eagle_serpent | D39: Заратустра + орёл + змея | E39: collective_subject | F39: includes | G39: включает | H39: n.serpent | I39: змея | J39: animal-symbol | K39: source_linked | L39: 1,1,1,3 | N39: 3 | O39: 3 | P39: [3] | Q39: |p3| | R39: seg.1.1.1.3 | S39: de+ru+en | T39: local_chain
A40: m029 | B40: source_edge | C40: n.triad_zarathustra_eagle_serpent | D40: Заратустра + орёл + змея | E40: collective_subject | F40: performs | G40: совершает | H40: ev.p4.morning_wait_for_sun | I40: утреннее ожидание солнца | J40: event | K40: source_linked | L40: 1,1,1,4 | N40: 4 | O40: 4 | P40: [4] | Q40: |p4| | R40: seg.1.1.1.4 | S40: de+ru+en | T40: local_chain
A41: m030 | B41: source_edge | C41: ev.p4.morning_wait_for_sun | D41: утреннее ожидание солнца | E41: event | F41: occurs_every | G41: повторяется каждое | H41: n.morning | I41: утро | J41: time | K41: source_linked | L41: 1,1,1,4 | N41: 4 | O41: 4 | P41: [4] | Q41: |p4| | R41: seg.1.1.1.4 | S41: de+ru+en | T41: local_chain
A42: m031 | B42: source_edge | C42: ev.p4.morning_wait_for_sun | D42: утреннее ожидание солнца | E42: event | F42: targets | G42: направлено к | H42: n.sun | I42: солнце / великое светило | J42: cosmic_entity | K42: source_linked | L42: 1,1,1,4 | N42: 4 | O42: 4 | P42: [4] | Q42: |p4| | R42: seg.1.1.1.4 | S42: de+ru+en | T42: local_chain
...

Sheet 16_Master_покрытие_1_12
A1: Coverage_view и аудит master-таблицы
A2: Generated coverage view. Read-only serving layer: формулы используют growth-safe ceiling ranges до 5000 строк master, без привязки к текущему концу.
A4: Файл-источник | B4: zarathustra_prologue_1_de_ru_en_merged.md
A5: Master sheet | B5: 15_Master_связность_1_12
A6: Всего строк | B6: ='15_Master_связность_1_12'!B5
A9: Абзац | B9: segment_id | C9: Всего строк | D9: source_edge | E9: bridge_edge | F9: principle_edge
A10: [1] | B10: seg.1.1.1.1 | C10: =COUNTIFS('15_Master_связность_1_12'!$N$12:$N$5000,"<="&VALUE(MID($A10,2,LEN($A10)-2)),'15_Master_связность_1_12'!$O$12:$O$5000,">="&VALUE(MID($A10,2,LEN($A10)-2))) | D10: =COUNTIFS('15_Master_связность_1_12'!$N$12:$N$5000,"<="&VALUE(MID($A10,2,LEN($A10)-2)),'15_Master_связность_1_12'!$O$12:$O$5000,">="&VALUE(MID($A10,2,LEN($A10)-2)),'15_Master_связность_1_12'!$B$12:$B$5000,"source_edge") | E10: =COUNTIFS('15_Master_связность_1_12'!$N$12:$N$5000,"<="&VALUE(MID($A10,2,LEN($A10)-2)),'15_Master_связность_1_12'!$O$12:$O$5000,">="&VALUE(MID($A10,2,LEN($A10)-2)),'15_Master_связность_1_12'!$B$12:$B$5000,"bridge_edge") | F10: =COUNTIFS('15_Master_связность_1_12'!$N$12:$N$5000,"<="&VALUE(MID($A10,2,LEN($A10)-2)),'15_Master_связность_1_12'!$O$12:$O$5000,">="&VALUE(MID($A10,2,LEN($A10)-2)),'15_Master_связность_1_12'!$B$12:$B$5000,"principle_edge")
A11: [2] | B11: seg.1.1.1.2 | C11: =COUNTIFS('15_Master_связность_1_12'!$N$12:$N$5000,"<="&VALUE(MID($A11,2,LEN($A11)-2)),'15_Master_связность_1_12'!$O$12:$O$5000,">="&VALUE(MID($A11,2,LEN($A11)-2))) | D11: =COUNTIFS('15_Master_связность_1_12'!$N$12:$N$5000,"<="&VALUE(MID($A11,2,LEN($A11)-2)),'15_Master_связность_1_12'!$O$12:$O$5000,">="&VALUE(MID($A11,2,LEN($A11)-2)),'15_Master_связность_1_12'!$B$12:$B$5000,"source_edge") | E11: =COUNTIFS('15_Master_связность_1_12'!$N$12:$N$5000,"<="&VALUE(MID($A11,2,LEN($A11)-2)),'15_Master_связность_1_12'!$O$12:$O$5000,">="&VALUE(MID($A11,2,LEN($A11)-2)),'15_Master_связность_1_12'!$B$12:$B$5000,"bridge_edge") | F11: =COUNTIFS('15_Master_связность_1_12'!$N$12:$N$5000,"<="&VALUE(MID($A11,2,LEN($A11)-2)),'15_Master_связность_1_12'!$O$12:$O$5000,">="&VALUE(MID($A11,2,LEN($A11)-2)),'15_Master_связность_1_12'!$B$12:$B$5000,"principle_edge")
A12: [3] | B12: seg.1.1.1.3 | C12: =COUNTIFS('15_Master_связность_1_12'!$N$12:$N$5000,"<="&VALUE(MID($A12,2,LEN($A12)-2)),'15_Master_связность_1_12'!$O$12:$O$5000,">="&VALUE(MID($A12,2,LEN($A12)-2))) | D12: =COUNTIFS('15_Master_связность_1_12'!$N$12:$N$5000,"<="&VALUE(MID($A12,2,LEN($A12)-2)),'15_Master_связность_1_12'!$O$12:$O$5000,">="&VALUE(MID($A12,2,LEN($A12)-2)),'15_Master_связность_1_12'!$B$12:$B$5000,"source_edge") | E12: =COUNTIFS('15_Master_связность_1_12'!$N$12:$N$5000,"<="&VALUE(MID($A12,2,LEN($A12)-2)),'15_Master_связность_1_12'!$O$12:$O$5000,">="&VALUE(MID($A12,2,LEN($A12)-2)),'15_Master_связность_1_12'!$B$12:$B$5000,"bridge_edge") | F12: =COUNTIFS('15_Master_связность_1_12'!$N$12:$N$5000,"<="&VALUE(MID($A12,2,LEN($A12)-2)),'15_Master_связность_1_12'!$O$12:$O$5000,">="&VALUE(MID($A12,2,LEN($A12)-2)),'15_Master_связность_1_12'!$B$12:$B$5000,"principle_edge")
A13: [4] | B13: seg.1.1.1.4 | C13: =COUNTIFS('15_Master_связность_1_12'!$N$12:$N$5000,"<="&VALUE(MID($A13,2,LEN($A13)-2)),'15_Master_связность_1_12'!$O$12:$O$5000,">="&VALUE(MID($A13,2,LEN($A13)-2))) | D13: =COUNTIFS('15_Master_связность_1_12'!$N$12:$N$5000,"<="&VALUE(MID($A13,2,LEN($A13)-2)),'15_Master_связность_1_12'!$O$12:$O$5000,">="&VALUE(MID($A13,2,LEN($A13)-2)),'15_Master_связность_1_12'!$B$12:$B$5000,"source_edge") | E13: =COUNTIFS('15_Master_связность_1_12'!$N$12:$N$5000,"<="&VALUE(MID($A13,2,LEN($A13)-2)),'15_Master_связность_1_12'!$O$12:$O$5000,">="&VALUE(MID($A13,2,LEN($A13)-2)),'15_Master_связность_1_12'!$B$12:$B$5000,"bridge_edge") | F13: =COUNTIFS('15_Master_связность_1_12'!$N$12:$N$5000,"<="&VALUE(MID($A13,2,LEN($A13)-2)),'15_Master_связность_1_12'!$O$12:$O$5000,">="&VALUE(MID($A13,2,LEN($A13)-2)),'15_Master_связность_1_12'!$B$12:$B$5000,"principle_edge")
A14: [5] | B14: seg.1.1.1.5 | C14: =COUNTIFS('15_Master_связность_1_12'!$N$12:$N$5000,"<="&VALUE(MID($A14,2,LEN($A14)-2)),'15_Master_связность_1_12'!$O$12:$O$5000,">="&VALUE(MID($A14,2,LEN($A14)-2))) | D14: =COUNTIFS('15_Master_связность_1_12'!$N$12:$N$5000,"<="&VALUE(MID($A14,2,LEN($A14)-2)),'15_Master_связность_1_12'!$O$12:$O$5000,">="&VALUE(MID($A14,2,LEN($A14)-2)),'15_Master_связность_1_12'!$B$12:$B$5000,"source_edge") | E14: =COUNTIFS('15_Master_связность_1_12'!$N$12:$N$5000,"<="&VALUE(MID($A14,2,LEN($A14)-2)),'15_Master_связность_1_12'!$O$12:$O$5000,">="&VALUE(MID($A14,2,LEN($A14)-2)),'15_Master_связность_1_12'!$B$12:$B$5000,"bridge_edge") | F14: =COUNTIFS('15_Master_связность_1_12'!$N$12:$N$5000,"<="&VALUE(MID($A14,2,LEN($A14)-2)),'15_Master_связность_1_12'!$O$12:$O$5000,">="&VALUE(MID($A14,2,LEN($A14)-2)),'15_Master_связность_1_12'!$B$12:$B$5000,"principle_edge")
A15: [6] | B15: seg.1.1.1.6 | C15: =COUNTIFS('15_Master_связность_1_12'!$N$12:$N$5000,"<="&VALUE(MID($A15,2,LEN($A15)-2)),'15_Master_связность_1_12'!$O$12:$O$5000,">="&VALUE(MID($A15,2,LEN($A15)-2))) | D15: =COUNTIFS('15_Master_связность_1_12'!$N$12:$N$5000,"<="&VALUE(MID($A15,2,LEN($A15)-2)),'15_Master_связность_1_12'!$O$12:$O$5000,">="&VALUE(MID($A15,2,LEN($A15)-2)),'15_Master_связность_1_12'!$B$12:$B$5000,"source_edge") | E15: =COUNTIFS('15_Master_связность_1_12'!$N$12:$N$5000,"<="&VALUE(MID($A15,2,LEN($A15)-2)),'15_Master_связность_1_12'!$O$12:$O$5000,">="&VALUE(MID($A15,2,LEN($A15)-2)),'15_Master_связность_1_12'!$B$12:$B$5000,"bridge_edge") | F15: =COUNTIFS('15_Master_связность_1_12'!$N$12:$N$5000,"<="&VALUE(MID($A15,2,LEN($A15)-2)),'15_Master_связность_1_12'!$O$12:$O$5000,">="&VALUE(MID($A15,2,LEN($A15)-2)),'15_Master_связность_1_12'!$B$12:$B$5000,"principle_edge")
A16: [7] | B16: seg.1.1.1.7 | C16: =COUNTIFS('15_Master_связность_1_12'!$N$12:$N$5000,"<="&VALUE(MID($A16,2,LEN($A16)-2)),'15_Master_связность_1_12'!$O$12:$O$5000,">="&VALUE(MID($A16,2,LEN($A16)-2))) | D16: =COUNTIFS('15_Master_связность_1_12'!$N$12:$N$5000,"<="&VALUE(MID($A16,2,LEN($A16)-2)),'15_Master_связность_1_12'!$O$12:$O$5000,">="&VALUE(MID($A16,2,LEN($A16)-2)),'15_Master_связность_1_12'!$B$12:$B$5000,"source_edge") | E16: =COUNTIFS('15_Master_связность_1_12'!$N$12:$N$5000,"<="&VALUE(MID($A16,2,LEN($A16)-2)),'15_Master_связность_1_12'!$O$12:$O$5000,">="&VALUE(MID($A16,2,LEN($A16)-2)),'15_Master_связность_1_12'!$B$12:$B$5000,"bridge_edge") | F16: =COUNTIFS('15_Master_связность_1_12'!$N$12:$N$5000,"<="&VALUE(MID($A16,2,LEN($A16)-2)),'15_Master_связность_1_12'!$O$12:$O$5000,">="&VALUE(MID($A16,2,LEN($A16)-2)),'15_Master_связность_1_12'!$B$12:$B$5000,"principle_edge")
